Workbook

Sheet Normal User
A1: DRCH – Normal User User Stories
A2: Story ID | B2: Front of Card – User Story | C2: Back of Card – Acceptance Criteria | D2: Source FR(s) | E2: Relevant NFR(s) | F2: Related Error Case(s) | G2: Epic | H2: Sprint
A3: US-N01 | B3: As a Normal User, I want to register an account, so that I can report incidents, donate and contribute aid. | C3: • Public sign-up creates a Normal User account only. • Duplicate or invalid registration is rejected with a clear message. • The dashboard is shown only after authentication. • Consent is captured as part of the registration input. | D3: NU-FR-01, AM-FR-11 | E3: NU-NFR-12 | F3: EH-01 | G3: E01 | H3: S1
A4: US-N02 | B4: As a Normal User, I want to log in and log out securely, so that my account and reports stay protected. | C4: • Valid credentials create a secure session. • Failed login shows a generic message that does not reveal whether the account exists. • Repeated failures trigger the configured rate limit or lockout. • I can request a password reset; the response is the same whether or not the account exists. | D4: NU-FR-01, AM-FR-11 | E4: NU-NFR-12 | F4: EH-02, EH-19 | G4: E01 | H4: S1
A5: US-N03 | B5: As a Normal User, I want to view and update my profile, so that my personal details stay current. | C5: • I can view and edit permitted profile fields. • Invalid fields are rejected. • I cannot change my own role. | D5: NU-FR-02 | E5: NU-NFR-05 | F5: EH-11 | G5: E04 | H5: S2
A6: US-N04 | B6: As a Normal User, I want to report an incident by choosing one of the three supported scenarios (Cyclone, Industrial Fire, Urban Flooding) and entering description, urgency and people affected, so that authorities learn about the emergency. | C6: • Scenario is chosen from a closed list of three and validated again on the server. • A unique incident ID and Submitted status are shown. • The system never claims the report is verified or dispatched. | D6: NU-FR-03 | E6: NU-NFR-01, NU-NFR-11 | F6: EH-01, EH-25 | G6: E04 | H6: S2
A7: US-N05 | B7: As a Normal User, I want to be told clearly when my situation is outside the three supported scenarios, so that I know to contact local emergency services instead. | C7: • An unsupported scenario value is rejected with a clear message. • The site shows a pointer to local emergency services. • No incident is created for an unsupported scenario. | D7: NU-FR-03 | E7: NU-NFR-01 | F7: EH-25 | G7: E04 | H7: S2
A8: US-N06 | B8: As a Normal User, I want to give the incident location by GPS, map point or manual address and add relevant details, so that responders can find the incident. | C8: • GPS or map point or manual address is accepted. • A map or address preview is shown and can be corrected. • If GPS or the map service is unavailable I can enter the location manually. | D8: NU-FR-04 | E8: NU-NFR-04 | F8: EH-01 | G8: E04 | H8: S2
A9: US-N07 | B9: As a Normal User, I want to attach photos or other permitted evidence to my report, so that staff can verify what is happening. | C9: • Only allowed types and sizes are accepted. • Each file shows its own state such as Pending Moderation. • Unsafe or corrupt files are rejected and unchecked content is never displayed. • I can remove my own evidence until it has been verified. | D9: NU-FR-05, DM-FR-18 | E9: NU-NFR-13 | F9: EH-03, EH-20 | G9: E04 | H9: S2
A10: US-N08 | B10: As a Normal User, I want to track the status, timeline, verified updates and closure reason of my own reports, so that I always know where my report stands. | C10: • Only my own reports are shown. • The timeline shows each state change. • The closure reason is shown once the incident is closed. • A report that is not mine is answered as not found, so its existence is not revealed. | D10: NU-FR-06 | E10: NU-NFR-09 | F10: EH-11 | G10: E04 | H10: S2
A11: US-N09 | B11: As a Normal User, I want to view my contribution history and retrieve receipts for confirmed donations, so that I have proof of what I contributed. | C11: • History lists my donations and aid contributions. • A receipt is available only for confirmed transactions. • Pending or failed donations show no receipt. | D11: NU-FR-06 | E11: NU-NFR-10 | F11: EH-07, EH-08 | G11: E09 | H11: S4
A12: US-N10 | B12: As a Normal User, I want to receive official alerts and updates about my reports and transactions, so that I stay informed. | C12: • In-app status is always available as the source of truth. • Queued, sent, delivered and failed states are visible. • Transient delivery failures are retried; opt-out is honoured where offered. | D12: NU-FR-07, AM-FR-09 | E12: AM-NFR-08 | F12: EH-13 | G12: E13 | H12: S3
A13: US-N11 | B13: As a Normal User, I want to read approved safety guidance for each of the three scenarios, so that I can protect myself and others. | C13: • Only approved, versioned content is shown. • Official status, source and last-update time are visible. • Stale or unapproved content is withheld. | D13: NU-FR-08, DM-FR-17 | E13: DM-NFR-15 | F13: – | G13: E11 | H13: S4
... A38: US-N36 | B38: As a Normal User, I want to exercise my data rights within retention limits (Optional), so that my data can be exported or deleted lawfully. | C38: • Requests are resolved within retention limits: completed, or refused with a recorded reason. • A deletion that did not happen is never reported as done. • Companion to US-N20: the request behaviour is specified there; this story verifies retention limits. | D38: NU-FR-14 (Optional) | E38: NU-NFR-15 (Optional) | F38: EH-26 | G38: E16 | H38: Cond

Sheet Disaster Management
A1: DRCH – Disaster Management User Stories
A2: Story ID | B2: Front of Card – User Story | C2: Back of Card – Acceptance Criteria | D2: Source FR(s) | E2: Relevant NFR(s) | F2: Related Error Case(s) | G2: Epic | H2: Sprint
A3: US-D01 | B3: As a Disaster Management staff member, I want to log in with MFA, so that only authorised staff access operational tools. | C3: • Valid credentials plus MFA give a secure session with my permission set. • Suspended or expired accounts and failed MFA are refused. • The dashboard loads only after authentication. | D3: DM-FR-01 | E3: DM-NFR-05 | F3: EH-02, EH-11 | G3: E01 | H3: S1
A4: US-D02 | B4: As a Disaster Management staff member, I want to see a consolidated dashboard of incidents, priorities, map, moderation queue and pending actions, so that I focus on what is urgent. | C4: • Filters narrow the data. • Overdue and escalated dispatches are surfaced. • Status and last-updated time are shown. | D4: DM-FR-02 | E4: DM-NFR-01, DM-NFR-03 | F4: – | G4: E05 | H4: S2
A5: US-D03 | B5: As a Disaster Management staff member, I want to review evidence and set a verification state with a rationale, so that only confirmed incidents are acted upon. | C5: • Decision, actor and time are saved. • The reporter is notified where appropriate. • Concurrent updates are detected and refused. | D5: DM-FR-03 | E5: DM-NFR-06 | F5: EH-05 | G5: E05 | H5: S2
A6: US-D04 | B6: As a Disaster Management staff member, I want to request more information from the reporter when evidence is insufficient, so that I can verify without dispatching on a guess. | C6: • The incident moves to Needs Information with a specific question for the reporter. • The report is not dispatched while unverified. • The reporter response returns it to the review queue. | D6: DM-FR-03, NU-FR-11 | E6: DM-NFR-05 | F6: EH-05 | G6: E05 | H6: S2
A7: US-D05 | B7: As a Disaster Management staff member, I want to see likely duplicate reports with the reason for the match, so that I avoid duplicate effort. | C7: • Candidates are shown, never auto-deleted. • I decide to link, merge or keep them. • Originals are preserved. | D7: DM-FR-04 | E7: DM-NFR-10 | F7: EH-04 | G7: E05 | H7: S2
A8: US-D06 | B8: As a Disaster Management staff member, I want to see an AI suggestion of scenario, urgency factors and triage evidence with confidence and uncertainty, so that I can triage faster and judge it. | C8: • AI output is clearly labelled advisory. • Factors, uncertainty and version metadata are shown where feasible. • A suggestion outside the three scenarios is flagged Out of Scope. | D8: DM-FR-05 | E8: DM-NFR-09 | F8: EH-06, EH-25 | G8: E06 | H8: S3
A9: US-D07 | B9: As a Disaster Management staff member, I want to accept, modify or reject the AI recommendation and record my decision, so that a human always makes the final call. | C9: • The AI recommendation is stored separately from my decision. • AI alone cannot finalise a critical decision. • If AI is unavailable I triage manually. | D9: DM-FR-05 | E9: DM-NFR-10 | F9: EH-06 | G9: E06 | H9: S3
A10: US-D08 | B10: As a Disaster Management staff member, I want to assign an operational priority with a recorded rationale, so that the right incidents are handled first. | C10: • Priority combines rules and my judgement. • The rationale is saved. • Queue, map and resource planning update. | D10: DM-FR-06 | E10: DM-NFR-06 | F10: – | G10: E06 | H10: S3
A11: US-D09 | B11: As a Disaster Management staff member, I want to see incidents, resources, routes and areas on an operational map, so that I understand where help is needed. | C11: • Pins show status and data freshness. • Coordinates are validated. • If the map service is down I still see list data. | D11: DM-FR-07 | E11: DM-NFR-08 | F11: – | G11: E07 | H11: S3
A12: US-D10 | B12: As a Disaster Management staff member, I want to track and assign teams, vehicles, supplies and support resources, so that I know what is available. | C12: • Availability is checked before assignment. • Conflicting or stale assignments are blocked. • Availability and conflicts are visible. • A reservation can be released, which makes the resource available again. | D12: DM-FR-08 | E12: DM-NFR-11 | F12: – | G12: E07 | H12: S3
A13: US-D11 | B13: As a Disaster Management staff member, I want to create and track a dispatch for a verified, prioritised incident with a resource, so that help reaches the scene. | C13: • Prerequisites are checked before creation. • States Requested, Acknowledged, Dispatched, Completed, Rejected, Failed or Escalated are shown; Escalated marks a dispatch that is still unacknowledged and is never shown as Acknowledged or Dispatched without a recorded confirmation. • Until an acknowledgement is recorded the dispatch shows Requested / Waiting; it becomes Acknowledged and then Dispatched only after a recorded confirmation. • If transmission fails or the team rejects the request, a failure or waiting state is shown and a safe retry or reassignment is allowed. • A false success is never displayed. • Dispatch completion is set only by a Disaster Management operator or a trusted integration, never inferred. | D13: DM-FR-09 | E13: DM-NFR-13 | F13: EH-12, EH-15, EH-16 | G13: E08 | H13: S3
... A43: US-D41 | B43: As a Disaster Management staff member, I want to follow documented manual fallbacks during a long integration outage (Optional), so that verification, dispatch recording and closure continue. | C43: • Manual procedures are documented. • Tabletop and degraded-mode drills pass. | D43: DM-FR-03, DM-FR-09, DM-FR-15 | E43: DM-NFR-16 (Optional) | F43: – | G43: E14 | H43: Cond

Sheet Application Management
A1: DRCH – Application Management User Stories
A2: Story ID | B2: Front of Card – User Story | C2: Back of Card – Acceptance Criteria | D2: Source FR(s) | E2: Relevant NFR(s) | F2: Related Error Case(s) | G2: Epic | H2: Sprint
A3: US-A01 | B3: As an Application Management administrator, I want to log in with MFA, so that platform administration is protected. | C3: • Valid credentials plus MFA give an admin session. • Invalid or disabled accounts and MFA failure are refused. • The console loads only after authentication. | D3: AM-FR-01 | E3: AM-NFR-06 | F3: EH-02 | G3: E01 | H3: S1
A4: US-A02 | B4: As an Application Management administrator, I want to create, suspend and reactivate staff, admin and user accounts, so that only vetted people have access. | C4: • Staff and admin accounts are created only by me. • Only the three roles can be assigned. • Before and after states are audited. | D4: AM-FR-02 | E4: AM-NFR-06 | F4: EH-11 | G4: E01 | H4: S1
A5: US-A03 | B5: As an Application Management administrator, I want to grant Publisher/Approver, moderator, closer and supervisor permissions inside Disaster Management, so that staff only get the authority they need. | C5: • Permissions are granted and revoked individually. • No fourth role can be created. • Changes take effect immediately and are audited. | D5: AM-FR-02 | E5: DM-NFR-05 | F5: EH-11 | G5: E01 | H5: S1
A6: US-A04 | B6: As an Application Management administrator, I want to be prevented from removing the last active administrator or escalating my own privileges, so that the platform is never left without control. | C6: • Removing the last admin is refused. • Self-escalation is refused and logged. | D6: AM-FR-02 | E6: AM-NFR-06 | F6: EH-11 | G6: E01 | H6: S1
A7: US-A05 | B7: As an Application Management administrator, I want to manage scenario, notification, timeout, escalation and duplicate-detection settings, so that behaviour can change safely. | C7: • Settings are versioned and audited. • The scenario setting can enable or disable only the three scenarios. • Attempts to add a scenario or role are refused. | D7: AM-FR-03 | E7: AM-NFR-01, AM-NFR-14 | F7: EH-24 | G7: E02 | H7: S1
A8: US-A06 | B8: As an Application Management administrator, I want to monitor services, queues, storage, integrations and the moderation backlog, so that I detect problems early. | C8: • A health dashboard shows current or last-known state. • Alerts are raised for failures and backlog. • Monitoring gaps are visible. | D8: AM-FR-04 | E8: AM-NFR-03 | F8: EH-21 | G8: E14 | H8: S5
A9: US-A07 | B9: As an Application Management administrator, I want to search and filter protected audit records of security and operational events, so that I can investigate and prove what happened. | C9: • Moderation decisions, closures and staff-recorded agency acknowledgements are included. • Logs are protected from alteration. • Access to logs is controlled. | D9: AM-FR-05 | E9: AM-NFR-09, DM-NFR-06 | F9: – | G9: E02 | H9: S1
A10: US-A08 | B10: As an Application Management administrator, I want to validate, correct and manage the lifecycle and retention of data, so that data quality stays high. | C10: • Corrections preserve traceability. • Unauthorised bulk changes are refused. | D10: AM-FR-06 | E10: AM-NFR-04 | F10: – | G10: E16 | H10: S4
A11: US-A09 | B11: As an Application Management administrator, I want to manage security controls, secrets and security incidents, so that the platform resists attacks. | C11: • Secrets are protected and rotated. • Every change is audited. • Actionable alerts are shown. | D11: AM-FR-07 | E11: AM-NFR-06 | F11: – | G11: E02 | H11: S1
A12: US-A10 | B12: As an Application Management administrator, I want to create, validate and restore backups, so that data can be recovered after a failure. | C12: • Backups are protected and integrity-checked. • Backup age, status and restore verification are shown. • Corrupt backups are detected. | D12: AM-FR-08 | E12: AM-NFR-05 | F12: – | G12: E14 | H12: S3
A13: US-A11 | B13: As an Application Management administrator, I want to configure notification channels, templates, routing and retry including the in-app fallback, so that notifications are reliable. | C13: • Configuration is validated, versioned and tested before activation. • The in-app channel is the fallback. | D13: AM-FR-09 | E13: AM-NFR-08 | F13: EH-13 | G13: E13 | H13: S1
... A34: US-A32 | B34: As an Application Management administrator, I want to have retention, archival and deletion schedules defined and enforced per data class (Optional), so that data is not kept longer than allowed. | C34: • Retention-policy and deletion-job tests pass. | D34: AM-FR-13 (Optional), AM-FR-06 | E34: AM-NFR-16 (Optional) | F34: EH-26 | G34: E16 | H34: Cond

Sheet External Parties
A1: DRCH – External Parties User Stories
A2: Story ID | B2: Front of Card – User Story | C2: Back of Card – Acceptance Criteria | D2: Source FR(s) | E2: Relevant NFR(s) | F2: Related Error Case(s) | G2: Epic | H2: Sprint
A3: US-X01 | B3: As an external agency contact, I want to receive a dispatch or coordination message from the Hub, so that I can act on it without needing an account. | C3: • Agencies hold no accounts or login. • Only information staff chose to share is sent. | D3: DM-FR-10, DM-FR-20 (Optional) | E3: NU-NFR-05 | F3: – | G3: E08 | H3: S3
A4: US-X02 | B4: As an external agency contact, I want to have my acknowledgement or progress recorded against the dispatch, so that the Hub shows the true dispatch state. | C4: • Staff or a trusted integration records the acknowledgement with timestamp and recorder. • Agency states map to internal dispatch states. | D4: DM-FR-10, DM-FR-09 | E4: DM-NFR-07 | F4: EH-17 | G4: E08 | H4: S3
A5: US-X03 | B5: As an external agency contact, I want to decline a dispatch and give a reason, so that the Hub can reassign help quickly. | C5: • The dispatch shows Rejected with reason and recorder. • Success is never shown. | D5: DM-FR-09, DM-FR-10 | E5: DM-NFR-07 | F5: EH-16 | G5: E08 | H5: S3
A6: US-X04 | B6: As an external agency contact, I want to send a late acknowledgement after escalation without breaking the record, so that history stays accurate. | C6: • Both events are kept in history. • The conflict is flagged for staff. • The late acknowledgement is recorded by staff or a trusted integration with the recorder stored; the agency has no login. | D6: DM-FR-10 | E6: DM-NFR-07 | F6: EH-17 | G6: E08 | H6: S3
A7: US-X05 | B7: As the payment gateway, I want to return a signed callback with transaction status to the Hub, so that donations are confirmed only when genuine. | C7: • Callback authenticity is verified. • Invalid or mismatched callbacks are flagged. | D7: NU-FR-09, AM-FR-10 | E7: NU-NFR-08, AM-NFR-07 | F7: EH-08 | G7: E09 | H7: S4
A8: US-X06 | B8: As the payment gateway, I want to remain unavailable without causing false donation success, so that donors are not misled. | C8: • Hub shows temporary unavailability. • Monitoring raises an alert. | D8: NU-FR-09, AM-FR-10 | E8: NU-NFR-04, AM-NFR-07 | F8: EH-09 | G8: E09 | H8: S4
A9: US-X07 | B9: As a notification provider, I want to report delivery success or failure for each message, so that the Hub can retry or fall back to in-app status. | C9: • Provider result is recorded. • Retries follow policy without duplicates. | D9: NU-FR-07, AM-FR-09 | E9: AM-NFR-08 | F9: EH-13 | G9: E08 | H9: S3
A10: US-X08 | B10: As the map service, I want to return map data for incident and resource display, so that staff can see locations. | C10: • Outage falls back to list and manual location. • Records are never corrupted by a map failure. | D10: DM-FR-07, NU-FR-04 | E10: DM-NFR-08, DM-NFR-07 | F10: EH-12 | G10: E07 | H10: S1
A11: US-X09 | B11: As the AI triage service, I want to provide advisory classification with confidence, so that staff can triage faster. | C11: • Low confidence or outage is marked uncertain. • Manual triage continues when AI is unavailable. | D11: DM-FR-05, DM-FR-04 | E11: DM-NFR-08, DM-NFR-09 | F11: EH-06 | G11: E06 | H11: S3
A12: US-X10 | B12: As the identity service, I want to authenticate users and staff, so that only valid people sign in. | C12: • Identity-service failure shows a safe error. • No session is created on failure. | D12: NU-FR-01, DM-FR-01, AM-FR-01 | E12: NU-NFR-04 | F12: EH-02 | G12: E01 | H12: S1

Sheet Epics
A1: Epics and sprint grouping (stories counted from the story sheets)
A2: Epic ID | B2: Epic | C2: Goal | D2: Stakeholders | E2: Stories | F2: Count | G2: S1 | H2: S2 | I2: S3 | J2: S4 | K2: S5 | L2: Conditional | M2: Done when
A3: E01 | B3: Identity, Authentication & Access Control | C3: Three-role sign-up, MFA login, server-side RBAC and account/permission administration. | D3: Normal User; Disaster Management; Application Management | E3: US-N01 US-N02 US-D01 US-A01 US-A02 US-A03 US-A04 US-D30 US-A22 US-X10 | F3: =SUM(G3:L3) -> 10 | G3: =COUNTIFS('Normal User'!$G$3:$G$60,$A3,'Normal User'!$H$3:$H$60,"S1")+COUNTIFS('Disaster Management'!$G$3:$G$60,$A3,'Disaster Management'!$H$3:$H$60,"S1")+COUNTIFS('Application Management'!$G$3:$G$60,$A3,'Application Management'!$H$3:$H$60,"S1")+COUNTIFS('External Parties'!$G$3:$G$60,$A3,'External Parties'!$H$3:$H$60,"S1") -> 10 | H3: =COUNTIFS('Normal User'!$G$3:$G$60,$A3,'Normal User'!$H$3:$H$60,"S2")+COUNTIFS('Disaster Management'!$G$3:$G$60,$A3,'Disaster Management'!$H$3:$H$60,"S2")+COUNTIFS('Application Management'!$G$3:$G$60,$A3,'Application Management'!$H$3:$H$60,"S2")+COUNTIFS('External Parties'!$G$3:$G$60,$A3,'External Parties'!$H$3:$H$60,"S2") -> 0 | I3: =COUNTIFS('Normal User'!$G$3:$G$60,$A3,'Normal User'!$H$3:$H$60,"S3")+COUNTIFS('Disaster Management'!$G$3:$G$60,$A3,'Disaster Management'!$H$3:$H$60,"S3")+COUNTIFS('Application Management'!$G$3:$G$60,$A3,'Application Management'!$H$3:$H$60,"S3")+COUNTIFS('External Parties'!$G$3:$G$60,$A3,'External Parties'!$H$3:$H$60,"S3") -> 0 | J3: =COUNTIFS('Normal User'!$G$3:$G$60,$A3,'Normal User'!$H$3:$H$60,"S4")+COUNTIFS('Disaster Management'!$G$3:$G$60,$A3,'Disaster Management'!$H$3:$H$60,"S4")+COUNTIFS('Application Management'!$G$3:$G$60,$A3,'Application Management'!$H$3:$H$60,"S4")+COUNTIFS('External Parties'!$G$3:$G$60,$A3,'External Parties'!$H$3:$H$60,"S4") -> 0 | K3: =COUNTIFS('Normal User'!$G$3:$G$60,$A3,'Normal User'!$H$3:$H$60,"S5")+COUNTIFS('Disaster Management'!$G$3:$G$60,$A3,'Disaster Management'!$H$3:$H$60,"S5")+COUNTIFS('Application Management'!$G$3:$G$60,$A3,'Application Management'!$H$3:$H$60,"S5")+COUNTIFS('External Parties'!$G$3:$G$60,$A3,'External Parties'!$H$3:$H$60,"S5") -> 0 | L3: =COUNTIFS('Normal User'!$G$3:$G$60,$A3,'Normal User'!$H$3:$H$60,"Cond")+COUNTIFS('Disaster Management'!$G$3:$G$60,$A3,'Disaster Management'!$H$3:$H$60,"Cond")+COUNTIFS('Application Management'!$G$3:$G$60,$A3,'Application Management'!$H$3:$H$60,"Cond")+COUNTIFS('External Parties'!$G$3:$G$60,$A3,'External Parties'!$H$3:$H$60,"Cond") -> 0 | M3: Each role reaches only its own area; last admin cannot be removed; no self-escalation.
A4: E02 | B4: Audit, Configuration & Security Governance | C4: Protected audit trail, versioned configuration with rollback, security controls and compliant deployment. | D4: Application Management; Disaster Management | E4: US-A05 US-A07 US-A09 US-A17 US-A20 US-A25 US-A27 US-A30 US-D31 US-A16 US-A31 | F4: =SUM(G4:L4) -> 11 | G4: =COUNTIFS('Normal User'!$G$3:$G$60,$A4,'Normal User'!$H$3:$H$60,"S1")+COUNTIFS('Disaster Management'!$G$3:$G$60,$A4,'Disaster Management'!$H$3:$H$60,"S1")+COUNTIFS('Application Management'!$G$3:$G$60,$A4,'Application Management'!$H$3:$H$60,"S1")+COUNTIFS('External Parties'!$G$3:$G$60,$A4,'External Parties'!$H$3:$H$60,"S1") -> 8 | H4: =COUNTIFS('Normal User'!$G$3:$G$60,$A4,'Normal User'!$H$3:$H$60,"S2")+COUNTIFS('Disaster Management'!$G$3:$G$60,$A4,'Disaster Management'!$H$3:$H$60,"S2")+COUNTIFS('Application Management'!$G$3:$G$60,$A4,'Application Management'!$H$3:$H$60,"S2")+COUNTIFS('External Parties'!$G$3:$G$60,$A4,'External Parties'!$H$3:$H$60,"S2") -> 1 | I4: =COUNTIFS('Normal User'!$G$3:$G$60,$A4,'Normal User'!$H$3:$H$60,"S3")+COUNTIFS('Disaster Management'!$G$3:$G$60,$A4,'Disaster Management'!$H$3:$H$60,"S3")+COUNTIFS('Application Management'!$G$3:$G$60,$A4,'Application Management'!$H$3:$H$60,"S3")+COUNTIFS('External Parties'!$G$3:$G$60,$A4,'External Parties'!$H$3:$H$60,"S3") -> 0 | J4: =COUNTIFS('Normal User'!$G$3:$G$60,$A4,'Normal User'!$H$3:$H$60,"S4")+COUNTIFS('Disaster Management'!$G$3:$G$60,$A4,'Disaster Management'!$H$3:$H$60,"S4")+COUNTIFS('Application Management'!$G$3:$G$60,$A4,'Application Management'!$H$3:$H$60,"S4")+COUNTIFS('External Parties'!$G$3:$G$60,$A4,'External Parties'!$H$3:$H$60,"S4") -> 0 | K4: =COUNTIFS('Normal User'!$G$3:$G$60,$A4,'Normal User'!$H$3:$H$60,"S5")+COUNTIFS('Disaster Management'!$G$3:$G$60,$A4,'Disaster Management'!$H$3:$H$60,"S5")+COUNTIFS('Application Management'!$G$3:$G$60,$A4,'Application Management'!$H$3:$H$60,"S5")+COUNTIFS('External Parties'!$G$3:$G$60,$A4,'External Parties'!$H$3:$H$60,"S5") -> 0 | L4: =COUNTIFS('Normal User'!$G$3:$G$60,$A4,'Normal User'!$H$3:$H$60,"Cond")+COUNTIFS('Disaster Management'!$G$3:$G$60,$A4,'Disaster Management'!$H$3:$H$60,"Cond")+COUNTIFS('Application Management'!$G$3:$G$60,$A4,'Application Management'!$H$3:$H$60,"Cond")+COUNTIFS('External Parties'!$G$3:$G$60,$A4,'External Parties'!$H$3:$H$60,"Cond") -> 2 | M4: Audit records cannot be altered; every config change is validated, attributable and reversible.
A5: E03 | B5: Abuse Protection & Content Safety | C5: Rate limits, moderation policy, evidence scanning, moderation queue and backlog control. | D5: Normal User; Disaster Management; Application Management | E5: US-A13 US-A14 US-A29 US-N33 US-N34 US-D22 US-D25 US-D39 | F5: =SUM(G5:L5) -> 8 | G5: =COUNTIFS('Normal User'!$G$3:$G$60,$A5,'Normal User'!$H$3:$H$60,"S1")+COUNTIFS('Disaster Management'!$G$3:$G$60,$A5,'Disaster Management'!$H$3:$H$60,"S1")+COUNTIFS('Application Management'!$G$3:$G$60,$A5,'Application Management'!$H$3:$H$60,"S1")+COUNTIFS('External Parties'!$G$3:$G$60,$A5,'External Parties'!$H$3:$H$60,"S1") -> 2 | H5: =COUNTIFS('Normal User'!$G$3:$G$60,$A5,'Normal User'!$H$3:$H$60,"S2")+COUNTIFS('Disaster Management'!$G$3:$G$60,$A5,'Disaster Management'!$H$3:$H$60,"S2")+COUNTIFS('Application Management'!$G$3:$G$60,$A5,'Application Management'!$H$3:$H$60,"S2")+COUNTIFS('External Parties'!$G$3:$G$60,$A5,'External Parties'!$H$3:$H$60,"S2") -> 5 | I5: =COUNTIFS('Normal User'!$G$3:$G$60,$A5,'Normal User'!$H$3:$H$60,"S3")+COUNTIFS('Disaster Management'!$G$3:$G$60,$A5,'Disaster Management'!$H$3:$H$60,"S3")+COUNTIFS('Application Management'!$G$3:$G$60,$A5,'Application Management'!$H$3:$H$60,"S3")+COUNTIFS('External Parties'!$G$3:$G$60,$A5,'External Parties'!$H$3:$H$60,"S3") -> 0 | J5: =COUNTIFS('Normal User'!$G$3:$G$60,$A5,'Normal User'!$H$3:$H$60,"S4")+COUNTIFS('Disaster Management'!$G$3:$G$60,$A5,'Disaster Management'!$H$3:$H$60,"S4")+COUNTIFS('Application Management'!$G$3:$G$60,$A5,'Application Management'!$H$3:$H$60,"S4")+COUNTIFS('External Parties'!$G$3:$G$60,$A5,'External Parties'!$H$3:$H$60,"S4") -> 0 | K5: =COUNTIFS('Normal User'!$G$3:$G$60,$A5,'Normal User'!$H$3:$H$60,"S5")+COUNTIFS('Disaster Management'!$G$3:$G$60,$A5,'Disaster Management'!$H$3:$H$60,"S5")+COUNTIFS('Application Management'!$G$3:$G$60,$A5,'Application Management'!$H$3:$H$60,"S5")+COUNTIFS('External Parties'!$G$3:$G$60,$A5,'External Parties'!$H$3:$H$60,"S5") -> 1 | L5: =COUNTIFS('Normal User'!$G$3:$G$60,$A5,'Normal User'!$H$3:$H$60,"Cond")+COUNTIFS('Disaster Management'!$G$3:$G$60,$A5,'Disaster Management'!$H$3:$H$60,"Cond")+COUNTIFS('Application Management'!$G$3:$G$60,$A5,'Application Management'!$H$3:$H$60,"Cond")+COUNTIFS('External Parties'!$G$3:$G$60,$A5,'External Parties'!$H$3:$H$60,"Cond") -> 0 | M5: No unapproved evidence is visible beyond reviewing staff; abuse controls hold without blocking genuine reports.
A6: E04 | B6: Incident Reporting, Tracking & Reporter Privacy | C6: Reporter journey: profile, three-scenario report, location, evidence, retry, status tracking, reply, correction and withdrawal. | D6: Normal User | E6: US-N03 US-N04 US-N05 US-N06 US-N07 US-N08 US-N16 US-N17 US-N19 US-N26 US-N30 US-N18 US-N35 | F6: =SUM(G6:L6) -> 13 | G6: =COUNTIFS('Normal User'!$G$3:$G$60,$A6,'Normal User'!$H$3:$H$60,"S1")+COUNTIFS('Disaster Management'!$G$3:$G$60,$A6,'Disaster Management'!$H$3:$H$60,"S1")+COUNTIFS('Application Management'!$G$3:$G$60,$A6,'Application Management'!$H$3:$H$60,"S1")+COUNTIFS('External Parties'!$G$3:$G$60,$A6,'External Parties'!$H$3:$H$60,"S1") -> 0 | H6: =COUNTIFS('Normal User'!$G$3:$G$60,$A6,'Normal User'!$H$3:$H$60,"S2")+COUNTIFS('Disaster Management'!$G$3:$G$60,$A6,'Disaster Management'!$H$3:$H$60,"S2")+COUNTIFS('Application Management'!$G$3:$G$60,$A6,'Application Management'!$H$3:$H$60,"S2")+COUNTIFS('External Parties'!$G$3:$G$60,$A6,'External Parties'!$H$3:$H$60,"S2") -> 11 | I6: =COUNTIFS('Normal User'!$G$3:$G$60,$A6,'Normal User'!$H$3:$H$60,"S3")+COUNTIFS('Disaster Management'!$G$3:$G$60,$A6,'Disaster Management'!$H$3:$H$60,"S3")+COUNTIFS('Application Management'!$G$3:$G$60,$A6,'Application Management'!$H$3:$H$60,"S3")+COUNTIFS('External Parties'!$G$3:$G$60,$A6,'External Parties'!$H$3:$H$60,"S3") -> 0 | J6: =COUNTIFS('Normal User'!$G$3:$G$60,$A6,'Normal User'!$H$3:$H$60,"S4")+COUNTIFS('Disaster Management'!$G$3:$G$60,$A6,'Disaster Management'!$H$3:$H$60,"S4")+COUNTIFS('Application Management'!$G$3:$G$60,$A6,'Application Management'!$H$3:$H$60,"S4")+COUNTIFS('External Parties'!$G$3:$G$60,$A6,'External Parties'!$H$3:$H$60,"S4") -> 0 | K6: =COUNTIFS('Normal User'!$G$3:$G$60,$A6,'Normal User'!$H$3:$H$60,"S5")+COUNTIFS('Disaster Management'!$G$3:$G$60,$A6,'Disaster Management'!$H$3:$H$60,"S5")+COUNTIFS('Application Management'!$G$3:$G$60,$A6,'Application Management'!$H$3:$H$60,"S5")+COUNTIFS('External Parties'!$G$3:$G$60,$A6,'External Parties'!$H$3:$H$60,"S5") -> 0 | L6: =COUNTIFS('Normal User'!$G$3:$G$60,$A6,'Normal User'!$H$3:$H$60,"Cond")+COUNTIFS('Disaster Management'!$G$3:$G$60,$A6,'Disaster Management'!$H$3:$H$60,"Cond")+COUNTIFS('Application Management'!$G$3:$G$60,$A6,'Application Management'!$H$3:$H$60,"Cond")+COUNTIFS('External Parties'!$G$3:$G$60,$A6,'External Parties'!$H$3:$H$60,"Cond") -> 2 | M6: A report is submitted once, tracked with clear states and visible only to authorised staff.
A7: E05 | B7: Verification & Staff Dashboard | C7: Staff dashboard, evidence review, verify/reject/request information, duplicate candidates. | D7: Disaster Management | E7: US-D02 US-D03 US-D04 US-D05 US-D26 | F7: =SUM(G7:L7) -> 5 | G7: =COUNTIFS('Normal User'!$G$3:$G$60,$A7,'Normal User'!$H$3:$H$60,"S1")+COUNTIFS('Disaster Management'!$G$3:$G$60,$A7,'Disaster Management'!$H$3:$H$60,"S1")+COUNTIFS('Application Management'!$G$3:$G$60,$A7,'Application Management'!$H$3:$H$60,"S1")+COUNTIFS('External Parties'!$G$3:$G$60,$A7,'External Parties'!$H$3:$H$60,"S1") -> 0 | H7: =COUNTIFS('Normal User'!$G$3:$G$60,$A7,'Normal User'!$H$3:$H$60,"S2")+COUNTIFS('Disaster Management'!$G$3:$G$60,$A7,'Disaster Management'!$H$3:$H$60,"S2")+COUNTIFS('Application Management'!$G$3:$G$60,$A7,'Application Management'!$H$3:$H$60,"S2")+COUNTIFS('External Parties'!$G$3:$G$60,$A7,'External Parties'!$H$3:$H$60,"S2") -> 5 | I7: =COUNTIFS('Normal User'!$G$3:$G$60,$A7,'Normal User'!$H$3:$H$60,"S3")+COUNTIFS('Disaster Management'!$G$3:$G$60,$A7,'Disaster Management'!$H$3:$H$60,"S3")+COUNTIFS('Application Management'!$G$3:$G$60,$A7,'Application Management'!$H$3:$H$60,"S3")+COUNTIFS('External Parties'!$G$3:$G$60,$A7,'External Parties'!$H$3:$H$60,"S3") -> 0 | J7: =COUNTIFS('Normal User'!$G$3:$G$60,$A7,'Normal User'!$H$3:$H$60,"S4")+COUNTIFS('Disaster Management'!$G$3:$G$60,$A7,'Disaster Management'!$H$3:$H$60,"S4")+COUNTIFS('Application Management'!$G$3:$G$60,$A7,'Application Management'!$H$3:$H$60,"S4")+COUNTIFS('External Parties'!$G$3:$G$60,$A7,'External Parties'!$H$3:$H$60,"S4") -> 0 | K7: =COUNTIFS('Normal User'!$G$3:$G$60,$A7,'Normal User'!$H$3:$H$60,"S5")+COUNTIFS('Disaster Management'!$G$3:$G$60,$A7,'Disaster Management'!$H$3:$H$60,"S5")+COUNTIFS('Application Management'!$G$3:$G$60,$A7,'Application Management'!$H$3:$H$60,"S5")+COUNTIFS('External Parties'!$G$3:$G$60,$A7,'External Parties'!$H$3:$H$60,"S5") -> 0 | L7: =COUNTIFS('Normal User'!$G$3:$G$60,$A7,'Normal User'!$H$3:$H$60,"Cond")+COUNTIFS('Disaster Management'!$G$3:$G$60,$A7,'Disaster Management'!$H$3:$H$60,"Cond")+COUNTIFS('Application Management'!$G$3:$G$60,$A7,'Application Management'!$H$3:$H$60,"Cond")+COUNTIFS('External Parties'!$G$3:$G$60,$A7,'External Parties'!$H$3:$H$60,"Cond") -> 0 | M7: A Submitted incident reaches Verified, Rejected or Needs Information with a rationale.
A8: E06 | B8: AI-Assisted Triage & Prioritisation | C8: Advisory AI with confidence and uncertainty; human accept/modify/reject; recorded priority. | D8: Disaster Management; External Parties (AI service) | E8: US-D06 US-D07 US-D08 US-D34 US-D35 US-X09 | F8: =SUM(G8:L8) -> 6 | G8: =COUNTIFS('Normal User'!$G$3:$G$60,$A8,'Normal User'!$H$3:$H$60,"S1")+COUNTIFS('Disaster Management'!$G$3:$G$60,$A8,'Disaster Management'!$H$3:$H$60,"S1")+COUNTIFS('Application Management'!$G$3:$G$60,$A8,'Application Management'!$H$3:$H$60,"S1")+COUNTIFS('External Parties'!$G$3:$G$60,$A8,'External Parties'!$H$3:$H$60,"S1") -> 0 | H8: =COUNTIFS('Normal User'!$G$3:$G$60,$A8,'Normal User'!$H$3:$H$60,"S2")+COUNTIFS('Disaster Management'!$G$3:$G$60,$A8,'Disaster Management'!$H$3:$H$60,"S2")+COUNTIFS('Application Management'!$G$3:$G$60,$A8,'Application Management'!$H$3:$H$60,"S2")+COUNTIFS('External Parties'!$G$3:$G$60,$A8,'External Parties'!$H$3:$H$60,"S2") -> 0 | I8: =COUNTIFS('Normal User'!$G$3:$G$60,$A8,'Normal User'!$H$3:$H$60,"S3")+COUNTIFS('Disaster Management'!$G$3:$G$60,$A8,'Disaster Management'!$H$3:$H$60,"S3")+COUNTIFS('Application Management'!$G$3:$G$60,$A8,'Application Management'!$H$3:$H$60,"S3")+COUNTIFS('External Parties'!$G$3:$G$60,$A8,'External Parties'!$H$3:$H$60,"S3") -> 6 | J8: =COUNTIFS('Normal User'!$G$3:$G$60,$A8,'Normal User'!$H$3:$H$60,"S4")+COUNTIFS('Disaster Management'!$G$3:$G$60,$A8,'Disaster Management'!$H$3:$H$60,"S4")+COUNTIFS('Application Management'!$G$3:$G$60,$A8,'Application Management'!$H$3:$H$60,"S4")+COUNTIFS('External Parties'!$G$3:$G$60,$A8,'External Parties'!$H$3:$H$60,"S4") -> 0 | K8: =COUNTIFS('Normal User'!$G$3:$G$60,$A8,'Normal User'!$H$3:$H$60,"S5")+COUNTIFS('Disaster Management'!$G$3:$G$60,$A8,'Disaster Management'!$H$3:$H$60,"S5")+COUNTIFS('Application Management'!$G$3:$G$60,$A8,'Application Management'!$H$3:$H$60,"S5")+COUNTIFS('External Parties'!$G$3:$G$60,$A8,'External Parties'!$H$3:$H$60,"S5") -> 0 | L8: =COUNTIFS('Normal User'!$G$3:$G$60,$A8,'Normal User'!$H$3:$H$60,"Cond")+COUNTIFS('Disaster Management'!$G$3:$G$60,$A8,'Disaster Management'!$H$3:$H$60,"Cond")+COUNTIFS('Application Management'!$G$3:$G$60,$A8,'Application Management'!$H$3:$H$60,"Cond")+COUNTIFS('External Parties'!$G$3:$G$60,$A8,'External Parties'!$H$3:$H$60,"Cond") -> 0 | M8: AI never finalises a decision; every decision is recorded with rationale.
A9: E07 | B9: Resources & Operational Map | C9: Operational map, resource tracking, reservation and release. | D9: Disaster Management; External Parties (map service) | E9: US-D09 US-D10 US-X08 | F9: =SUM(G9:L9) -> 3 | G9: =COUNTIFS('Normal User'!$G$3:$G$60,$A9,'Normal User'!$H$3:$H$60,"S1")+COUNTIFS('Disaster Management'!$G$3:$G$60,$A9,'Disaster Management'!$H$3:$H$60,"S1")+COUNTIFS('Application Management'!$G$3:$G$60,$A9,'Application Management'!$H$3:$H$60,"S1")+COUNTIFS('External Parties'!$G$3:$G$60,$A9,'External Parties'!$H$3:$H$60,"S1") -> 1 | H9: =COUNTIFS('Normal User'!$G$3:$G$60,$A9,'Normal User'!$H$3:$H$60,"S2")+COUNTIFS('Disaster Management'!$G$3:$G$60,$A9,'Disaster Management'!$H$3:$H$60,"S2")+COUNTIFS('Application Management'!$G$3:$G$60,$A9,'Application Management'!$H$3:$H$60,"S2")+COUNTIFS('External Parties'!$G$3:$G$60,$A9,'External Parties'!$H$3:$H$60,"S2") -> 0 | I9: =COUNTIFS('Normal User'!$G$3:$G$60,$A9,'Normal User'!$H$3:$H$60,"S3")+COUNTIFS('Disaster Management'!$G$3:$G$60,$A9,'Disaster Management'!$H$3:$H$60,"S3")+COUNTIFS('Application Management'!$G$3:$G$60,$A9,'Application Management'!$H$3:$H$60,"S3")+COUNTIFS('External Parties'!$G$3:$G$60,$A9,'External Parties'!$H$3:$H$60,"S3") -> 2 | J9: =COUNTIFS('Normal User'!$G$3:$G$60,$A9,'Normal User'!$H$3:$H$60,"S4")+COUNTIFS('Disaster Management'!$G$3:$G$60,$A9,'Disaster Management'!$H$3:$H$60,"S4")+COUNTIFS('Application Management'!$G$3:$G$60,$A9,'Application Management'!$H$3:$H$60,"S4")+COUNTIFS('External Parties'!$G$3:$G$60,$A9,'External Parties'!$H$3:$H$60,"S4") -> 0 | K9: =COUNTIFS('Normal User'!$G$3:$G$60,$A9,'Normal User'!$H$3:$H$60,"S5")+COUNTIFS('Disaster Management'!$G$3:$G$60,$A9,'Disaster Management'!$H$3:$H$60,"S5")+COUNTIFS('Application Management'!$G$3:$G$60,$A9,'Application Management'!$H$3:$H$60,"S5")+COUNTIFS('External Parties'!$G$3:$G$60,$A9,'External Parties'!$H$3:$H$60,"S5") -> 0 | L9: =COUNTIFS('Normal User'!$G$3:$G$60,$A9,'Normal User'!$H$3:$H$60,"Cond")+COUNTIFS('Disaster Management'!$G$3:$G$60,$A9,'Disaster Management'!$H$3:$H$60,"Cond")+COUNTIFS('Application Management'!$G$3:$G$60,$A9,'Application Management'!$H$3:$H$60,"Cond")+COUNTIFS('External Parties'!$G$3:$G$60,$A9,'External Parties'!$H$3:$H$60,"Cond") -> 0 | M9: Resources cannot be double-booked and the map shows incidents, resources and areas.
A10: E08 | B10: Dispatch & Agency Coordination | C10: Dispatch lifecycle, acknowledgement, rejection, timeout and escalation, agency messaging and late acknowledgement. | D10: Disaster Management; Normal User; External Parties (agencies) | E10: US-D11 US-D12 US-D13 US-D14 US-D38 US-N32 US-X01 US-X02 US-X03 US-X04 US-X07 US-D32 US-D24 | F10: =SUM(G10:L10) -> 13 | G10: =COUNTIFS('Normal User'!$G$3:$G$60,$A10,'Normal User'!$H$3:$H$60,"S1")+COUNTIFS('Disaster Management'!$G$3:$G$60,$A10,'Disaster Management'!$H$3:$H$60,"S1")+COUNTIFS('Application Management'!$G$3:$G$60,$A10,'Application Management'!$H$3:$H$60,"S1")+COUNTIFS('External Parties'!$G$3:$G$60,$A10,'External Parties'!$H$3:$H$60,"S1") -> 0 | H10: =COUNTIFS('Normal User'!$G$3:$G$60,$A10,'Normal User'!$H$3:$H$60,"S2")+COUNTIFS('Disaster Management'!$G$3:$G$60,$A10,'Disaster Management'!$H$3:$H$60,"S2")+COUNTIFS('Application Management'!$G$3:$G$60,$A10,'Application Management'!$H$3:$H$60,"S2")+COUNTIFS('External Parties'!$G$3:$G$60,$A10,'External Parties'!$H$3:$H$60,"S2") -> 0 | I10: =COUNTIFS('Normal User'!$G$3:$G$60,$A10,'Normal User'!$H$3:$H$60,"S3")+COUNTIFS('Disaster Management'!$G$3:$G$60,$A10,'Disaster Management'!$H$3:$H$60,"S3")+COUNTIFS('Application Management'!$G$3:$G$60,$A10,'Application Management'!$H$3:$H$60,"S3")+COUNTIFS('External Parties'!$G$3:$G$60,$A10,'External Parties'!$H$3:$H$60,"S3") -> 12 | J10: =COUNTIFS('Normal User'!$G$3:$G$60,$A10,'Normal User'!$H$3:$H$60,"S4")+COUNTIFS('Disaster Management'!$G$3:$G$60,$A10,'Disaster Management'!$H$3:$H$60,"S4")+COUNTIFS('Application Management'!$G$3:$G$60,$A10,'Application Management'!$H$3:$H$60,"S4")+COUNTIFS('External Parties'!$G$3:$G$60,$A10,'External Parties'!$H$3:$H$60,"S4") -> 0 | K10: =COUNTIFS('Normal User'!$G$3:$G$60,$A10,'Normal User'!$H$3:$H$60,"S5")+COUNTIFS('Disaster Management'!$G$3:$G$60,$A10,'Disaster Management'!$H$3:$H$60,"S5")+COUNTIFS('Application Management'!$G$3:$G$60,$A10,'Application Management'!$H$3:$H$60,"S5")+COUNTIFS('External Parties'!$G$3:$G$60,$A10,'External Parties'!$H$3:$H$60,"S5") -> 0 | L10: =COUNTIFS('Normal User'!$G$3:$G$60,$A10,'Normal User'!$H$3:$H$60,"Cond")+COUNTIFS('Disaster Management'!$G$3:$G$60,$A10,'Disaster Management'!$H$3:$H$60,"Cond")+COUNTIFS('Application Management'!$G$3:$G$60,$A10,'Application Management'!$H$3:$H$60,"Cond")+COUNTIFS('External Parties'!$G$3:$G$60,$A10,'External Parties'!$H$3:$H$60,"Cond") -> 1 | M10: State advances only on a recorded confirmation and no false success is shown.
A11: E09 | B11: Donations & Payments | C11: Campaigns, gateway handoff, signed callbacks, Pending/Confirmed/Failed states, receipts, donor privacy and payment monitoring. | D11: Normal User; Disaster Management; Application Management; External Parties (gateway) | E11: US-D20 US-N12 US-N13 US-N28 US-N29 US-X05 US-X06 US-N09 US-N31 US-D16 US-A12 US-A23 | F11: =SUM(G11:L11) -> 12 | G11: =COUNTIFS('Normal User'!$G$3:$G$60,$A11,'Normal User'!$H$3:$H$60,"S1")+COUNTIFS('Disaster Management'!$G$3:$G$60,$A11,'Disaster Management'!$H$3:$H$60,"S1")+COUNTIFS('Application Management'!$G$3:$G$60,$A11,'Application Management'!$H$3:$H$60,"S1")+COUNTIFS('External Parties'!$G$3:$G$60,$A11,'External Parties'!$H$3:$H$60,"S1") -> 0 | H11: =COUNTIFS('Normal User'!$G$3:$G$60,$A11,'Normal User'!$H$3:$H$60,"S2")+COUNTIFS('Disaster Management'!$G$3:$G$60,$A11,'Disaster Management'!$H$3:$H$60,"S2")+COUNTIFS('Application Management'!$G$3:$G$60,$A11,'Application Management'!$H$3:$H$60,"S2")+COUNTIFS('External Parties'!$G$3:$G$60,$A11,'External Parties'!$H$3:$H$60,"S2") -> 0 | I11: =COUNTIFS('Normal User'!$G$3:$G$60,$A11,'Normal User'!$H$3:$H$60,"S3")+COUNTIFS('Disaster Management'!$G$3:$G$60,$A11,'Disaster Management'!$H$3:$H$60,"S3")+COUNTIFS('Application Management'!$G$3:$G$60,$A11,'Application Management'!$H$3:$H$60,"S3")+COUNTIFS('External Parties'!$G$3:$G$60,$A11,'External Parties'!$H$3:$H$60,"S3") -> 0 | J11: =COUNTIFS('Normal User'!$G$3:$G$60,$A11,'Normal User'!$H$3:$H$60,"S4")+COUNTIFS('Disaster Management'!$G$3:$G$60,$A11,'Disaster Management'!$H$3:$H$60,"S4")+COUNTIFS('Application Management'!$G$3:$G$60,$A11,'Application Management'!$H$3:$H$60,"S4")+COUNTIFS('External Parties'!$G$3:$G$60,$A11,'External Parties'!$H$3:$H$60,"S4") -> 11 | K11: =COUNTIFS('Normal User'!$G$3:$G$60,$A11,'Normal User'!$H$3:$H$60,"S5")+COUNTIFS('Disaster Management'!$G$3:$G$60,$A11,'Disaster Management'!$H$3:$H$60,"S5")+COUNTIFS('Application Management'!$G$3:$G$60,$A11,'Application Management'!$H$3:$H$60,"S5")+COUNTIFS('External Parties'!$G$3:$G$60,$A11,'External Parties'!$H$3:$H$60,"S5") -> 1 | L11: =COUNTIFS('Normal User'!$G$3:$G$60,$A11,'Normal User'!$H$3:$H$60,"Cond")+COUNTIFS('Disaster Management'!$G$3:$G$60,$A11,'Disaster Management'!$H$3:$H$60,"Cond")+COUNTIFS('Application Management'!$G$3:$G$60,$A11,'Application Management'!$H$3:$H$60,"Cond")+COUNTIFS('External Parties'!$G$3:$G$60,$A11,'External Parties'!$H$3:$H$60,"Cond") -> 0 | M11: No false receipt, no double charge, gateway outage never shows false success.
A12: E10 | B12: Physical Aid Contributions | C12: Aid registration, verification, allocation to approved needs and delivery confirmation. | D12: Normal User; Disaster Management | E12: US-N14 US-N15 US-D17 US-D23 | F12: =SUM(G12:L12) -> 4 | G12: =COUNTIFS('Normal User'!$G$3:$G$60,$A12,'Normal User'!$H$3:$H$60,"S1")+COUNTIFS('Disaster Management'!$G$3:$G$60,$A12,'Disaster Management'!$H$3:$H$60,"S1")+COUNTIFS('Application Management'!$G$3:$G$60,$A12,'Application Management'!$H$3:$H$60,"S1")+COUNTIFS('External Parties'!$G$3:$G$60,$A12,'External Parties'!$H$3:$H$60,"S1") -> 0 | H12: =COUNTIFS('Normal User'!$G$3:$G$60,$A12,'Normal User'!$H$3:$H$60,"S2")+COUNTIFS('Disaster Management'!$G$3:$G$60,$A12,'Disaster Management'!$H$3:$H$60,"S2")+COUNTIFS('Application Management'!$G$3:$G$60,$A12,'Application Management'!$H$3:$H$60,"S2")+COUNTIFS('External Parties'!$G$3:$G$60,$A12,'External Parties'!$H$3:$H$60,"S2") -> 0 | I12: =COUNTIFS('Normal User'!$G$3:$G$60,$A12,'Normal User'!$H$3:$H$60,"S3")+COUNTIFS('Disaster Management'!$G$3:$G$60,$A12,'Disaster Management'!$H$3:$H$60,"S3")+COUNTIFS('Application Management'!$G$3:$G$60,$A12,'Application Management'!$H$3:$H$60,"S3")+COUNTIFS('External Parties'!$G$3:$G$60,$A12,'External Parties'!$H$3:$H$60,"S3") -> 0 | J12: =COUNTIFS('Normal User'!$G$3:$G$60,$A12,'Normal User'!$H$3:$H$60,"S4")+COUNTIFS('Disaster Management'!$G$3:$G$60,$A12,'Disaster Management'!$H$3:$H$60,"S4")+COUNTIFS('Application Management'!$G$3:$G$60,$A12,'Application Management'!$H$3:$H$60,"S4")+COUNTIFS('External Parties'!$G$3:$G$60,$A12,'External Parties'!$H$3:$H$60,"S4") -> 3 | K12: =COUNTIFS('Normal User'!$G$3:$G$60,$A12,'Normal User'!$H$3:$H$60,"S5")+COUNTIFS('Disaster Management'!$G$3:$G$60,$A12,'Disaster Management'!$H$3:$H$60,"S5")+COUNTIFS('Application Management'!$G$3:$G$60,$A12,'Application Management'!$H$3:$H$60,"S5")+COUNTIFS('External Parties'!$G$3:$G$60,$A12,'External Parties'!$H$3:$H$60,"S5") -> 0 | L12: =COUNTIFS('Normal User'!$G$3:$G$60,$A12,'Normal User'!$H$3:$H$60,"Cond")+COUNTIFS('Disaster Management'!$G$3:$G$60,$A12,'Disaster Management'!$H$3:$H$60,"Cond")+COUNTIFS('Application Management'!$G$3:$G$60,$A12,'Application Management'!$H$3:$H$60,"Cond")+COUNTIFS('External Parties'!$G$3:$G$60,$A12,'External Parties'!$H$3:$H$60,"Cond") -> 1 | M12: Delivered needs an authorised confirmation.
A13: E11 | B13: Public Communication & Safety Content | C13: Versioned approval and publication of public updates and safety guidance. | D13: Normal User; Disaster Management | E13: US-D15 US-D21 US-D40 US-N11 US-N21 | F13: =SUM(G13:L13) -> 5 | G13: =COUNTIFS('Normal User'!$G$3:$G$60,$A13,'Normal User'!$H$3:$H$60,"S1")+COUNTIFS('Disaster Management'!$G$3:$G$60,$A13,'Disaster Management'!$H$3:$H$60,"S1")+COUNTIFS('Application Management'!$G$3:$G$60,$A13,'Application Management'!$H$3:$H$60,"S1")+COUNTIFS('External Parties'!$G$3:$G$60,$A13,'External Parties'!$H$3:$H$60,"S1") -> 0 | H13: =COUNTIFS('Normal User'!$G$3:$G$60,$A13,'Normal User'!$H$3:$H$60,"S2")+COUNTIFS('Disaster Management'!$G$3:$G$60,$A13,'Disaster Management'!$H$3:$H$60,"S2")+COUNTIFS('Application Management'!$G$3:$G$60,$A13,'Application Management'!$H$3:$H$60,"S2")+COUNTIFS('External Parties'!$G$3:$G$60,$A13,'External Parties'!$H$3:$H$60,"S2") -> 0 | I13: =COUNTIFS('Normal User'!$G$3:$G$60,$A13,'Normal User'!$H$3:$H$60,"S3")+COUNTIFS('Disaster Management'!$G$3:$G$60,$A13,'Disaster Management'!$H$3:$H$60,"S3")+COUNTIFS('Application Management'!$G$3:$G$60,$A13,'Application Management'!$H$3:$H$60,"S3")+COUNTIFS('External Parties'!$G$3:$G$60,$A13,'External Parties'!$H$3:$H$60,"S3") -> 0 | J13: =COUNTIFS('Normal User'!$G$3:$G$60,$A13,'Normal User'!$H$3:$H$60,"S4")+COUNTIFS('Disaster Management'!$G$3:$G$60,$A13,'Disaster Management'!$H$3:$H$60,"S4")+COUNTIFS('Application Management'!$G$3:$G$60,$A13,'Application Management'!$H$3:$H$60,"S4")+COUNTIFS('External Parties'!$G$3:$G$60,$A13,'External Parties'!$H$3:$H$60,"S4") -> 4 | K13: =COUNTIFS('Normal User'!$G$3:$G$60,$A13,'Normal User'!$H$3:$H$60,"S5")+COUNTIFS('Disaster Management'!$G$3:$G$60,$A13,'Disaster Management'!$H$3:$H$60,"S5")+COUNTIFS('Application Management'!$G$3:$G$60,$A13,'Application Management'!$H$3:$H$60,"S5")+COUNTIFS('External Parties'!$G$3:$G$60,$A13,'External Parties'!$H$3:$H$60,"S5") -> 0 | L13: =COUNTIFS('Normal User'!$G$3:$G$60,$A13,'Normal User'!$H$3:$H$60,"Cond")+COUNTIFS('Disaster Management'!$G$3:$G$60,$A13,'Disaster Management'!$H$3:$H$60,"Cond")+COUNTIFS('Application Management'!$G$3:$G$60,$A13,'Application Management'!$H$3:$H$60,"Cond")+COUNTIFS('External Parties'!$G$3:$G$60,$A13,'External Parties'!$H$3:$H$60,"Cond") -> 1 | M13: Unapproved content is never public; every published version is attributable.
A14: E12 | B14: Incident Closure & Analytics | C14: Incident closure with dependency checks, analytics and metric definitions. | D14: Disaster Management | E14: US-D19 US-D18 US-D37 | F14: =SUM(G14:L14) -> 3 | G14: =COUNTIFS('Normal User'!$G$3:$G$60,$A14,'Normal User'!$H$3:$H$60,"S1")+COUNTIFS('Disaster Management'!$G$3:$G$60,$A14,'Disaster Management'!$H$3:$H$60,"S1")+COUNTIFS('Application Management'!$G$3:$G$60,$A14,'Application Management'!$H$3:$H$60,"S1")+COUNTIFS('External Parties'!$G$3:$G$60,$A14,'External Parties'!$H$3:$H$60,"S1") -> 0 | H14: =COUNTIFS('Normal User'!$G$3:$G$60,$A14,'Normal User'!$H$3:$H$60,"S2")+COUNTIFS('Disaster Management'!$G$3:$G$60,$A14,'Disaster Management'!$H$3:$H$60,"S2")+COUNTIFS('Application Management'!$G$3:$G$60,$A14,'Application Management'!$H$3:$H$60,"S2")+COUNTIFS('External Parties'!$G$3:$G$60,$A14,'External Parties'!$H$3:$H$60,"S2") -> 0 | I14: =COUNTIFS('Normal User'!$G$3:$G$60,$A14,'Normal User'!$H$3:$H$60,"S3")+COUNTIFS('Disaster Management'!$G$3:$G$60,$A14,'Disaster Management'!$H$3:$H$60,"S3")+COUNTIFS('Application Management'!$G$3:$G$60,$A14,'Application Management'!$H$3:$H$60,"S3")+COUNTIFS('External Parties'!$G$3:$G$60,$A14,'External Parties'!$H$3:$H$60,"S3") -> 0 | J14: =COUNTIFS('Normal User'!$G$3:$G$60,$A14,'Normal User'!$H$3:$H$60,"S4")+COUNTIFS('Disaster Management'!$G$3:$G$60,$A14,'Disaster Management'!$H$3:$H$60,"S4")+COUNTIFS('Application Management'!$G$3:$G$60,$A14,'Application Management'!$H$3:$H$60,"S4")+COUNTIFS('External Parties'!$G$3:$G$60,$A14,'External Parties'!$H$3:$H$60,"S4") -> 0 | K14: =COUNTIFS('Normal User'!$G$3:$G$60,$A14,'Normal User'!$H$3:$H$60,"S5")+COUNTIFS('Disaster Management'!$G$3:$G$60,$A14,'Disaster Management'!$H$3:$H$60,"S5")+COUNTIFS('Application Management'!$G$3:$G$60,$A14,'Application Management'!$H$3:$H$60,"S5")+COUNTIFS('External Parties'!$G$3:$G$60,$A14,'External Parties'!$H$3:$H$60,"S5") -> 3 | L14: =COUNTIFS('Normal User'!$G$3:$G$60,$A14,'Normal User'!$H$3:$H$60,"Cond")+COUNTIFS('Disaster Management'!$G$3:$G$60,$A14,'Disaster Management'!$H$3:$H$60,"Cond")+COUNTIFS('Application Management'!$G$3:$G$60,$A14,'Application Management'!$H$3:$H$60,"Cond")+COUNTIFS('External Parties'!$G$3:$G$60,$A14,'External Parties'!$H$3:$H$60,"Cond") -> 0 | M14: Every incident ends in a clear final state; metrics show definitions and freshness.
... A18: E16 | B18: Data Lifecycle & Privacy Rights | C18: Data validation, retention and lifecycle; data export and deletion rights. | D18: Application Management; Normal User | E18: US-A08 US-N20 US-N36 US-A15 US-A32 | F18: =SUM(G18:L18) -> 5 | G18: =COUNTIFS('Normal User'!$G$3:$G$60,$A18,'Normal User'!$H$3:$H$60,"S1")+COUNTIFS('Disaster Management'!$G$3:$G$60,$A18,'Disaster Management'!$H$3:$H$60,"S1")+COUNTIFS('Application Management'!$G$3:$G$60,$A18,'Application Management'!$H$3:$H$60,"S1")+COUNTIFS('External Parties'!$G$3:$G$60,$A18,'External Parties'!$H$3:$H$60,"S1") -> 0 | H18: =COUNTIFS('Normal User'!$G$3:$G$60,$A18,'Normal User'!$H$3:$H$60,"S2")+COUNTIFS('Disaster Management'!$G$3:$G$60,$A18,'Disaster Management'!$H$3:$H$60,"S2")+COUNTIFS('Application Management'!$G$3:$G$60,$A18,'Application Management'!$H$3:$H$60,"S2")+COUNTIFS('External Parties'!$G$3:$G$60,$A18,'External Parties'!$H$3:$H$60,"S2") -> 0 | I18: =COUNTIFS('Normal User'!$G$3:$G$60,$A18,'Normal User'!$H$3:$H$60,"S3")+COUNTIFS('Disaster Management'!$G$3:$G$60,$A18,'Disaster Management'!$H$3:$H$60,"S3")+COUNTIFS('Application Management'!$G$3:$G$60,$A18,'Application Management'!$H$3:$H$60,"S3")+COUNTIFS('External Parties'!$G$3:$G$60,$A18,'External Parties'!$H$3:$H$60,"S3") -> 0 | J18: =COUNTIFS('Normal User'!$G$3:$G$60,$A18,'Normal User'!$H$3:$H$60,"S4")+COUNTIFS('Disaster Management'!$G$3:$G$60,$A18,'Disaster Management'!$H$3:$H$60,"S4")+COUNTIFS('Application Management'!$G$3:$G$60,$A18,'Application Management'!$H$3:$H$60,"S4")+COUNTIFS('External Parties'!$G$3:$G$60,$A18,'External Parties'!$H$3:$H$60,"S4") -> 1 | K18: =COUNTIFS('Normal User'!$G$3:$G$60,$A18,'Normal User'!$H$3:$H$60,"S5")+COUNTIFS('Disaster Management'!$G$3:$G$60,$A18,'Disaster Management'!$H$3:$H$60,"S5")+COUNTIFS('Application Management'!$G$3:$G$60,$A18,'Application Management'!$H$3:$H$60,"S5")+COUNTIFS('External Parties'!$G$3:$G$60,$A18,'External Parties'!$H$3:$H$60,"S5") -> 0 | L18: =COUNTIFS('Normal User'!$G$3:$G$60,$A18,'Normal User'!$H$3:$H$60,"Cond")+COUNTIFS('Disaster Management'!$G$3:$G$60,$A18,'Disaster Management'!$H$3:$H$60,"Cond")+COUNTIFS('Application Management'!$G$3:$G$60,$A18,'Application Management'!$H$3:$H$60,"Cond")+COUNTIFS('External Parties'!$G$3:$G$60,$A18,'External Parties'!$H$3:$H$60,"Cond") -> 4 | M18: Corrections preserve traceability; retention rules enforced; rights requests handled within limits.
A19: Total | F19: =SUM(F3:F18) -> 119 | G19: =SUM(G3:G18) -> 22 | H19: =SUM(H3:H18) -> 22 | I19: =SUM(I3:I18) -> 22 | J19: =SUM(J3:J18) -> 20 | K19: =SUM(K3:K18) -> 21 | L19: =SUM(L3:L18) -> 12
A20: Check | B20: =IF(F19=119,"OK: all 119 stories are in exactly one epic","ERROR: story count differs from 119") -> OK: all 119 stories are in exactly one epic
A21: Note | B21: An epic may span sprints when its stories depend on different features; the sprint plan lists what is completed later. Conditional stories are the 12 Optional stories and are not counted in S1-S5. Epic-level conflicts are CR-57 to CR-68 in the Conflict Register.

Sheet Coverage
A1: DRCH – FR / NFR / Error Case Coverage
A2: Requirement | B2: Type | C2: Optional? | D2: Covered by story ID(s)
A3: NU-FR-01 | B3: FR | C3: No | D3: US-N01, US-N02, US-X10
A4: NU-FR-02 | B4: FR | C4: No | D4: US-N03, US-N26
A5: NU-FR-03 | B5: FR | C5: No | D5: US-N04, US-N05, US-N19, US-N22, US-N23, US-N24, US-N25, US-N27, US-N32, US-N33
A6: NU-FR-04 | B6: FR | C6: No | D6: US-N06, US-N26, US-X08
A7: NU-FR-05 | B7: FR | C7: No | D7: US-N07, US-N34
A8: NU-FR-06 | B8: FR | C8: No | D8: US-N08, US-N09, US-N23, US-N30
A9: NU-FR-07 | B9: FR | C9: No | D9: US-N10, US-N32, US-X07
A10: NU-FR-08 | B10: FR | C10: No | D10: US-N11, US-N25
A11: NU-FR-09 | B11: FR | C11: No | D11: US-N12, US-N13, US-N28, US-N29, US-N31, US-X05, US-X06
A12: NU-FR-10 | B12: FR | C12: No | D12: US-N14, US-N15
A13: NU-FR-11 | B13: FR | C13: No | D13: US-N16, US-D04
... A124: EH-26 | B124: Error case | C124: Yes | D124: US-N20, US-N36, US-A15, US-A32

Sheet Notes
A1: Notes on the SRS-based user stories
A3: 1 | B3: Source: 'Disaster Response Coordination Hub — Final SRS (Revised)', 29 Sep 2026. All IDs below are the SRS IDs.
A4: 2 | B4: Stakeholders in the SRS: three roles only (Normal User, Disaster Management, Application Management). Publisher/Approver, moderator, closer and supervisor are permissions inside Disaster Management, so those stories use that wording, not new roles.
A5: 3 | B5: External agencies, the payment gateway, notification provider, map service, AI service and identity service are integrations, not logins. They are covered in the 'External Parties' section.
A6: 4 | B6: Requirements marked (Optional) in the SRS are marked (Optional) here too: NU-FR-13/14/15, DM-FR-19/20, AM-FR-13/14, NU-NFR-14/15, DM-NFR-16, AM-NFR-15/16 and EH-26.
A7: 5 | B7: Every FR (49), NFR (47) and error case (26) appears in at least one story; see the Coverage section. A sixth column 'Related Error Case(s)' was added to the reference layout.
A8: 6 | B8: Numeric targets are not invented, as in the SRS ('proposed target until approved by [named approver]').
A9: 7 | B9: Review pass (11 Oct 2026): stories were checked against the Final SRS (Revised). Cells changed in this pass are filled red; see the Change Log, Conflict Register, FR/NFR Traceability and Summary sheets. Open issues remain; full compliance is not claimed.
A10: 8 | B10: Final review pass (11 Oct 2026): SRS Section 13 (scenarios) and Section 15 (routes) were checked against all stories; corrections and the resolution of earlier open issues are listed in the Change Log and Conflict Register. Open items at that pass were later restated: see Notes 9 to 11, the Summary and the Conflict Register for current counts (four business decisions, CR-25 to CR-28; open or partly open items CR-22 to CR-28 and CR-46 to CR-50). None is marked resolved.
A11: 9 | B11: Verification pass v2 (11 Oct 2026): CR-22, CR-23 and CR-25 to CR-28 and CR-46 to CR-48 were re-checked against the SRS. CR-22 and CR-23 are interpretations that need SRS-owner confirmation and are no longer counted as resolved. Two further SRS-level items were recorded (CR-49, CR-50). Mandatory decisions remain open; full compliance is not claimed.
A12: 10 | B12: Verification pass v3 (11 Oct 2026): NFR/FR cross-references, specifications 7.1–7.11, Section 12 and the registers were re-checked. Two story errors were fixed (CR-51, CR-52) and the issue counts were reconciled by status bucket (see Summary). Business decisions and SRS corrections remain open; full compliance is not claimed.
A13: 11 | B13: Verification pass v4 (11 Oct 2026): story text checked against the sprint plan. Permission names aligned (CR-53), US-D37 wording clarified (CR-54), stale counts in Notes 8 and Summary V10 corrected (CR-55), and the count of Optional stories (12, including US-N21) recorded (CR-56). Business decisions and SRS corrections remain open; full compliance is not claimed.
A14: 12 | B14: Epic pass (v5): all 119 stories are grouped into 16 epics (sheet Epics) and each story carries an Epic and a Sprint column. Cross-epic conflicts are CR-57 to CR-68; ten are resolved by staged delivery or design rules and two stay open (CR-66 permission model, CR-68 backup retention).

Sheet Change Log
A1: Change Log
A2: Change ID | B2: Sheet | C2: Story / Req ID | D2: Cell | E2: Field | F2: Original value | G2: Corrected value | H2: Reason | I2: Source reference | J2: Conflict ID
A3: CL-01 | B3: Normal User | C3: US-N15 | D3: B17 | E3: Front of Card – User Story | F3: As a Normal User, I want to see each stage of my aid contribution (Registered, Verified, Allocated, In Transit, Delivered or Failed) separately, so that I can follow it to delivery. | G3: As a Normal User, I want to see each stage of my aid contribution (Registered / Pending Verification, Verified or Rejected, Allocated, In Transit, Delivered or Failed) separately, so that I can follow it to delivery. | H3: Stage list omitted the Pending Verification and Rejected outcomes that the SRS defines for physical aid; aligned terminology so each stage can be shown separately. | I3: SRS 7.4 Internal processing and Flow; NU-FR-10; EH-10 | J3: CR-01
A4: CL-02 | B4: Normal User | C4: US-N16 | D4: C18 | E4: Back of Card – Acceptance Criteria | F4: • I can add text, evidence or a corrected location. • The response is stored with my identity and time. • The incident returns to the review queue; I cannot answer for another user or a closed incident. | G4: • I can add text, evidence or a corrected location. • The response is stored with my identity and time. • The incident returns to the review queue; I cannot answer for another user or a closed incident. • A response is accepted only while the incident is in the Needs Information state; a response after the response window has expired is refused with a clear message. | H4: Added the NU-FR-11 precondition (Needs Information state) and the expired-window failure condition that the criteria did not state. | I4: NU-FR-11 Description and Failure; EH-05 | J4: CR-02
A5: CL-03 | B5: Normal User | C5: US-N19 | D5: D21 | E5: Source FR(s) | F5: NU-FR-13 (Optional), NU-FR-03 | G5: NU-FR-03, NU-FR-13 (Optional) | H5: Story is core (retry safety is required by EH-12 and NU-NFR-08) but listed the Optional NU-FR-13 first. Core FR now leads and the Optional dependency is marked; the dependency itself is logged as an open issue. | I5: NU-FR-03; NU-FR-13 (Optional); EH-12; NU-NFR-08; SRS s.14 open decision 2 | J5: CR-03
A6: CL-04 | B6: Normal User | C6: US-N24 | D6: C26 | E6: Back of Card – Acceptance Criteria | F6: • Common actions respond within the approved target. • Targets are set after workload analysis. | G6: • Common actions respond within the approved target. • Targets are proposed after workload analysis and remain proposed until approved by the named approver. | H6: Criterion said targets are "set"; the SRS says every measurable target is only proposed until a named approver approves it. | I6: NU-NFR-03; SRS s.2 Assumptions; s.8 preamble | J6: CR-04
A7: CL-05 | B7: Normal User | C7: US-N33 | D7: C35 | E7: Back of Card – Acceptance Criteria | F7: • Abuse controls contain bots without blocking genuine reports. • False-positive tests pass. | G7: • Abuse controls contain bots without blocking genuine reports. • False-positive tests pass. • When a limit is reached I see a clear message that does not reveal the threshold, with a pointer to an alternative route for a genuine emergency. | H7: Added the user-facing behaviour required when a rate limit is hit; no story stated the emergency-alternative pointer. | I7: AM-FR-11 Application reaction; SRS 7.10; EH-18 | J7: CR-05
